Workbook

Sheet Lists
A1: Category
A2: Housing - Rent
A3: Groceries
A4: Dining & Coffee
A5: Utilities & Phone
A6: Transport
A7: Fitness & Memberships
A8: Health & Pharmacy
A9: Shopping
A10: Beauty & Personal Care
A11: Home & Household
A12: Entertainment & Experiences
... A23: Income - Other Credit

Sheet Transactions
A1: Date | B1: Description | C1: Details | D1: Category | E1: Amount (AUD) | F1: Debit (AUD) | G1: Credit (AUD) | H1: Statement Balance (AUD) | I1: Month | J1: Parse Status | K1: Source Page | L1: Raw PDF text
A2: 45962 | B2: HAWAIIAN1734212522763 PARIS FR | C2: Card xx6220 USD 23.00 | Value Date 29/10/2025 | D2: Other | E2: -35.16 | F2: 35.16 | G2: 0 | H2: 7624.16 | I2: 2025-11 | J2: High confidence | K2: 1 | L2: 01 Nov HAWAIIAN1734212522763 PARIS FR FRA | Card xx6220 USD 23.00 | Value Date 29/10/2025 35.16 7,624.16 CR | 0303
A3: 45962 | B3: International Transaction Fee | C3: Value Date 29/10/2025 | D3: Bank Fees | E3: -1.23 | F3: 1.23 | G3: 0 | H3: 7622.93 | I3: 2025-11 | J3: High confidence | K3: 1 | L3: 01 Nov International Transaction Fee | Value Date 29/10/2025 1.23 7,622.93 CR | ZZ258R3
A4: 45962 | B4: THE TASTE OF ASIAN PTY MASCOT AUS | C4: Card xx0018 | Value Date 30/10/2025 | D4: Other | E4: -20 | F4: 20 | G4: 0 | H4: 7602.93 | I4: 2025-11 | J4: High confidence | K4: 1 | L4: 01 Nov THE TASTE OF ASIAN PTY MASCOT AUS | Card xx0018 | Value Date 30/10/2025 20.00 7,602.93 CR | 3162.10484.1.6
A5: 45962 | B5: UBER *TRIP HELP.UBER.C 14518236738 | C5: Card xx0018 | Value Date 31/10/2025 | TELLO MOBILE ATLANTA GA USA | Card xx0018 USD 11.78 | Value Date 30/10/2025 | D5: Transport | E5: -5 | F5: 5 | G5: 0 | H5: 7597.93 | I5: 2025-11 | J5: High confidence | K5: 1 | L5: 01 Nov UBER *TRIP HELP.UBER.C 14518236738 AU AU | Card xx0018 | Value Date 31/10/2025 5.00 7,597.93 CR | * | * 01 Nov TELLO MOBILE ATLANTA GA USA | Card xx0018 USD 11.78 | Value Date 30/10/2025 18.01 7,579.92 CR
A6: 45962 | B6: International Transaction Fee | C6: Value Date 29/10/2025 | D6: Bank Fees | E6: -18.64 | F6: 18.64 | G6: 0 | H6: 7579.29 | I6: 2025-11 | J6: Amount mismatch: columns -0.63, balance delta -18.64; used balance | K6: 1 | L6: 01 Nov International Transaction Fee | Value Date 29/10/2025 0.63 7,579.29 CR
A7: 45962 | B7: Liv Eat Mascot NS AUS | C7: Card xx0018 | Value Date 29/10/2025 | D7: Other | E7: -6.09 | F7: 6.09 | G7: 0 | H7: 7573.2 | I7: 2025-11 | J7: High confidence | K7: 1 | L7: 01 Nov Liv Eat Mascot NS AUS | Card xx0018 | Value Date 29/10/2025 6.09 7,573.20 CR
A8: 45962 | B8: UBER *TRIP HELP.UBER.C 14518236738 | C8: Card xx0018 | Value Date 30/10/2025 | D8: Transport | E8: -5 | F8: 5 | G8: 0 | H8: 7568.2 | I8: 2025-11 | J8: High confidence | K8: 1 | L8: 01 Nov UBER *TRIP HELP.UBER.C 14518236738 AU AU | Card xx0018 | Value Date 30/10/2025 5.00 7,568.20 CR
A9: 45962 | B9: UBER *TRIP HELP.UBER.C 14518236738 | C9: Card xx0018 | Value Date 30/10/2025 | D9: Transport | E9: -67.79 | F9: 67.79 | G9: 0 | H9: 7500.41 | I9: 2025-11 | J9: High confidence | K9: 1 | L9: 01 Nov UBER *TRIP HELP.UBER.C 14518236738 AU AU | Card xx0018 | Value Date 30/10/2025 67.79 7,500.41 CR
A10: 45962 | B10: UBER *TRIP HELP.UBER.C 14518236738 | C10: Card xx0018 | Value Date 30/10/2025 | D10: Transport | E10: -5 | F10: 5 | G10: 0 | H10: 7495.41 | I10: 2025-11 | J10: High confidence | K10: 2 | L10: 01 Nov UBER *TRIP HELP.UBER.C 14518236738 AU AU | Card xx0018 | Value Date 30/10/2025 5.00 7,495.41 CR
A11: 45964 | B11: Direct Debit 545383 Telstra Services | C11: hn4vs2tp | D11: Utilities & Phone | E11: -10 | F11: 10 | G11: 0 | H11: 7485.41 | I11: 2025-11 | J11: High confidence | K11: 2 | L11: 03 Nov Direct Debit 545383 Telstra Services | hn4vs2tp 10.00 7,485.41 CR
A12: 45964 | B12: Direct Debit 012495 GU HEALTH D/DBT | C12: 29497443 | D12: Health & Pharmacy | E12: -65.76 | F12: 65.76 | G12: 0 | H12: 7419.65 | I12: 2025-11 | J12: High confidence | K12: 2 | L12: 03 Nov Direct Debit 012495 GU HEALTH D/DBT | 29497443 65.76 7,419.65 CR
A13: 45965 | B13: KEN'S MARKET 75-116 SEATTLE WA | C13: Card xx0018 USD 2.75 | Value Date 01/11/2025 | D13: Other | E13: -4.21 | F13: 4.21 | G13: 0 | H13: 7415.44 | I13: 2025-11 | J13: High confidence | K13: 2 | L13: 04 Nov KEN'S MARKET 75-116 SEATTLE WA USA | Card xx0018 USD 2.75 | Value Date 01/11/2025 4.21 7,415.44 CR
... A37: 45968 | B37: TH*Greencare Clinics Sydney NS AUS | C37: Card xx0018 | Value Date 06/11/2025 | SQ *Y'NO DY Dee Why AU | D37: Health & Pharmacy | E37: -99 | F37: 99 | G37: 0 | H37: 5030.95 | I37: 2025-11 | J37: High confidence | K37: 3 | L37: 07 Nov TH*Greencare Clinics Sydney NS AUS | 0303 Card xx0018 | Value Date 06/11/2025 99.00 5,030.95 CR | ZZ258R3 07 Nov SQ *Y'NO DY Dee Why AU 4.50 5,026.45 CR
A38: 45968 | B38: SQ *TOASTIESMITH TGV Sydney AU | D38: Other | E38: -13.13 | F38: 13.13 | G38: 0 | H38: 5017.82 | I38: 2025-11 | J38: Amount mismatch: columns -8.63, balance delta -13.13; used balance | K38: 3 | L38: 07 Nov SQ *TOASTIESMITH TGV Sydney AU 8.63 5,017.82 CR
A39: 45969 | B39: TRANSPORTFORNSW OPAL CHIPPENDALE | C39: Card xx6220 | Value Date 07/11/2025 | D39: Transport | E39: -60 | F39: 60 | G39: 0 | H39: 4957.82 | I39: 2025-11 | J39: High confidence | K39: 3 | L39: 08 Nov TRANSPORTFORNSW OPAL CHIPPENDALE AUS | 3162.10485.2.6 Card xx6220 | Value Date 07/11/2025 60.00 4,957.82 CR
A40: 45969 | B40: UBER *TRIP HELP.UBER.C 14518236738 | C40: Card xx0018 | Value Date 06/11/2025 | D40: Transport | E40: -103.02 | F40: 103.02 | G40: 0 | H40: 4854.8 | I40: 2025-11 | J40: High confidence | K40: 3 | L40: 08 Nov UBER *TRIP HELP.UBER.C 14518236738 AU AU | Card xx0018 | Value Date 06/11/2025 103.02 4,854.80 CR
A41: 45969 | B41: SQ *PAGES & PAGES HONO Honolulu | C41: Card xx0018 USD 3.99 | Value Date 06/11/2025 | D41: Other | E41: -6.18 | F41: 6.18 | G41: 0 | H41: 4848.62 | I41: 2025-11 | J41: High confidence | K41: 3 | L41: 08 Nov SQ *PAGES & PAGES HONO Honolulu HI USA | Card xx0018 USD 3.99 | Value Date 06/11/2025 6.18 4,848.62 CR
A42: 45969 | B42: International Transaction Fee | C42: Value Date 05/11/2025 | D42: Bank Fees | E42: -0.22 | F42: 0.22 | G42: 0 | H42: 4848.4 | I42: 2025-11 | J42: High confidence | K42: 3 | L42: 08 Nov International Transaction Fee | Value Date 05/11/2025 0.22 4,848.40 CR
A43: 45969 | B43: WENDY'S 13238-615 SEATTLE WA | C43: Card xx0018 USD 5.81 | Value Date 06/11/2025 | D43: Other | E43: -8.97 | F43: 8.97 | G43: 0 | H43: 4839.43 | I43: 2025-11 | J43: High confidence | K43: 3 | L43: 08 Nov WENDY'S 13238-615 SEATTLE WA USA | Card xx0018 USD 5.81 | Value Date 06/11/2025 8.97 4,839.43 CR
A44: 45969 | B44: International Transaction Fee | C44: Value Date 05/11/2025 | D44: Bank Fees | E44: -0.31 | F44: 0.31 | G44: 0 | H44: 4839.12 | I44: 2025-11 | J44: High confidence | K44: 3 | L44: 08 Nov International Transaction Fee | Value Date 05/11/2025 0.31 4,839.12 CR
A45: 45969 | B45: PIKE&PINE ST2275 SEATTLE WA USA | C45: Card xx0018 USD 5.82 | Value Date 06/11/2025 | D45: Other | E45: -8.98 | F45: 8.98 | G45: 0 | H45: 4830.14 | I45: 2025-11 | J45: High confidence | K45: 4 | L45: 08 Nov PIKE&PINE ST2275 SEATTLE WA USA | Card xx0018 USD 5.82 | Value Date 06/11/2025 8.98 4,830.14 CR
A46: 45969 | B46: International Transaction Fee | C46: Value Date 05/11/2025 | D46: Bank Fees | E46: -0.31 | F46: 0.31 | G46: 0 | H46: 4829.83 | I46: 2025-11 | J46: High confidence | K46: 4 | L46: 08 Nov International Transaction Fee | Value Date 05/11/2025 0.31 4,829.83 CR
A47: 45969 | B47: SQ *SACREBLEU | CANELE dee why AU | D47: Dining & Coffee | E47: -8.12 | F47: 8.12 | G47: 0 | H47: 4821.71 | I47: 2025-11 | J47: High confidence | K47: 4 | L47: 08 Nov SQ *SACREBLEU | CANELE dee why AU 8.12 4,821.71 CR
A48: 45969 | B48: COLES 0784 DEE WHY AU | D48: Groceries | E48: -24.89 | F48: 24.89 | G48: 0 | H48: 4796.82 | I48: 2025-11 | J48: High confidence | K48: 4 | L48: 08 Nov COLES 0784 DEE WHY AU 24.89 4,796.82 CR
A49: 45970 | B49: SQ *Y'NO DY Dee Why AU | D49: Other | E49: -4.5 | F49: 4.5 | G49: 0 | H49: 4792.32 | I49: 2025-11 | J49: High confidence | K49: 4 | L49: 09 Nov SQ *Y'NO DY Dee Why AU 4.50 4,792.32 CR
A50: 45970 | B50: SQ *SACREBLEU | CANELE dee why AU | D50: Dining & Coffee | E50: -14.2 | F50: 14.2 | G50: 0 | H50: 4778.12 | I50: 2025-11 | J50: High confidence | K50: 4 | L50: 09 Nov SQ *SACREBLEU | CANELE dee why AU 14.20 4,778.12 CR
A51: 45971 | B51: Subway Kent 24 Market StrAU | D51: Dining & Coffee | E51: -4.5 | F51: 4.5 | G51: 0 | H51: 4773.62 | I51: 2025-11 | J51: High confidence | K51: 4 | L51: 10 Nov Subway Kent 24 Market StrAU 4.50 4,773.62 CR
A52: 45971 | B52: Subway Dee Why 7 Oaks AvenueAU | D52: Dining & Coffee | E52: -2.95 | F52: 2.95 | G52: 0 | H52: 4770.67 | I52: 2025-11 | J52: High confidence | K52: 4 | L52: 10 Nov Subway Dee Why 7 Oaks AvenueAU 2.95 4,770.67 CR
A53: 45972 | B53: SP TEA LIFE NORTH SAINT M NS AUS | C53: Card xx6220 | Value Date 09/11/2025 | D53: Dining & Coffee | E53: -64.7 | F53: 64.7 | G53: 0 | H53: 4705.97 | I53: 2025-11 | J53: High confidence | K53: 4 | L53: 11 Nov SP TEA LIFE NORTH SAINT M NS AUS | Card xx6220 | Value Date 09/11/2025 64.70 4,705.97 CR
A54: 45972 | B54: Return UBER *TRIP HELP.UBER.C | C54: Card xx0018 | Value Date 09/11/2025 | D54: Income - Refund/Reimbursement | E54: 0.02 | F54: 0 | G54: 0.02 | H54: 4705.99 | I54: 2025-11 | J54: High confidence | K54: 4 | L54: 11 Nov Return UBER *TRIP HELP.UBER.C 1451823673 | Card xx0018 | Value Date 09/11/2025 0.02 4,705.99 CR
A55: 45972 | B55: UBER *TRIP HELP.UBER.C 14518236738 | C55: Card xx0018 | Value Date 09/11/2025 | D55: Transport | E55: -3 | F55: 3 | G55: 0 | H55: 4702.99 | I55: 2025-11 | J55: High confidence | K55: 4 | L55: 11 Nov UBER *TRIP HELP.UBER.C 14518236738 AU AU | Card xx0018 | Value Date 09/11/2025 3.00 4,702.99 CR
A56: 45972 | B56: GREENHOUSE KIRRIBILLI Kirribilli NS | C56: Card xx0018 | Value Date 09/11/2025 | D56: Other | E56: -43.2 | F56: 43.2 | G56: 0 | H56: 4659.79 | I56: 2025-11 | J56: High confidence | K56: 4 | L56: 11 Nov GREENHOUSE KIRRIBILLI Kirribilli NS AUS | Card xx0018 | Value Date 09/11/2025 43.20 4,659.79 CR
A57: 45972 | B57: UBER *TRIP HELP.UBER.C 14518236738 | C57: Card xx0018 | Value Date 09/11/2025 | D57: Transport | E57: -12.75 | F57: 12.75 | G57: 0 | H57: 4647.04 | I57: 2025-11 | J57: High confidence | K57: 4 | L57: 11 Nov UBER *TRIP HELP.UBER.C 14518236738 AU AU | V06.00.37 | Card xx0018 | Value Date 09/11/2025 12.75 4,647.04 CR
A58: 45972 | B58: BWS LIQUOR 1653 KIRRIBILLI NS AUS | C58: Card xx0018 | Value Date 09/11/2025 | D58: Dining & Coffee | E58: -6.5 | F58: 6.5 | G58: 0 | H58: 4640.54 | I58: 2025-11 | J58: High confidence | K58: 4 | L58: 11 Nov BWS LIQUOR 1653 KIRRIBILLI NS AUS | Card xx0018 | SL.R3.S141.D338.O Value Date 09/11/2025 6.50 4,640.54 CR
A59: 45972 | B59: UBER *TRIP HELP.UBER.C 14518236738 | C59: Card xx0018 | Value Date 09/11/2025 | D59: Transport | E59: -16.03 | F59: 16.03 | G59: 0 | H59: 4624.51 | I59: 2025-11 | J59: High confidence | K59: 4 | L59: 11 Nov UBER *TRIP HELP.UBER.C 14518236738 AU AU | Card xx0018 | Value Date 09/11/2025 16.03 4,624.51 CR | 0303
A60: 45972 | B60: COLES 0784 DEE WHY 02 AUS | C60: Card xx0018 | Value Date 07/11/2025 | D60: Groceries | E60: -64.39 | F60: 64.39 | G60: 0 | H60: 4560.12 | I60: 2025-11 | J60: High confidence | K60: 4 | L60: 11 Nov COLES 0784 DEE WHY 02 AUS | Card xx0018 | ZZ258R3 | Value Date 07/11/2025 64.39 4,560.12 CR
A61: 45972 | B61: GARDENIA ESPRESSO SYDNEY NS AUS | C61: Card xx0018 | Value Date 07/11/2025 | D61: Dining & Coffee | E61: -11.5 | F61: 11.5 | G61: 0 | H61: 4548.62 | I61: 2025-11 | J61: High confidence | K61: 4 | L61: 11 Nov GARDENIA ESPRESSO SYDNEY NS AUS | Card xx0018 | 3162.10485.2.6 Value Date 07/11/2025 11.50 4,548.62 CR
A62: 45972 | B62: B5 Cafe Narraweena NS AUS | C62: Card xx0018 | Value Date 08/11/2025 | D62: Dining & Coffee | E62: -22.73 | F62: 22.73 | G62: 0 | H62: 4525.89 | I62: 2025-11 | J62: High confidence | K62: 4 | L62: 11 Nov B5 Cafe Narraweena NS AUS | Card xx0018 | Value Date 08/11/2025 22.73 4,525.89 CR
A63: 45972 | B63: UBER *EATS HELP.UBER.C Sydney AU | C63: Card xx0018 | Value Date 07/11/2025 | D63: Other | E63: -258.58 | F63: 258.58 | G63: 0 | H63: 4267.31 | I63: 2025-11 | J63: High confidence | K63: 4 | L63: 11 Nov UBER *EATS HELP.UBER.C Sydney AU AUS | Card xx0018 | Value Date 07/11/2025 258.58 4,267.31 CR
...

Sheet Monthly Summary
A1: Month | B1: Recurring Direct Credit (AUD) | C1: Refunds / Other Income (AUD) | D1: Transfer In (AUD) | E1: Spending excl. Transfer Out (AUD) | F1: Transfer Out (AUD) | G1: Net Cash Flow (AUD)
A2: 2025-11 | B2: =SUMIFS(Transactions!$G$2:$G$201,Transactions!$I$2:$I$201,$A2,Transactions!$D$2:$D$201,"Income - Recurring Direct Credit") -> 0 | C2: =SUMIFS(Transactions!$G$2:$G$201,Transactions!$I$2:$I$201,$A2,Transactions!$D$2:$D$201,"Income - Refund/Reimbursement")+SUMIFS(Transactions!$G$2:$G$201,Transactions!$I$2:$I$201,$A2,Transactions!$D$2:$D$201,"Income - Other Credit") -> 0 | D2: =SUMIFS(Transactions!$G$2:$G$201,Transactions!$I$2:$I$201,$A2,Transactions!$D$2:$D$201,"Transfer In") -> 0 | E2: =SUMIFS(Transactions!$F$2:$F$201,Transactions!$I$2:$I$201,$A2)-SUMIFS(Transactions!$F$2:$F$201,Transactions!$I$2:$I$201,$A2,Transactions!$D$2:$D$201,"Transfer Out") -> 0 | F2: =SUMIFS(Transactions!$F$2:$F$201,Transactions!$I$2:$I$201,$A2,Transactions!$D$2:$D$201,"Transfer Out") -> 0 | G2: =B2+C2+D2-E2-F2 -> 0
A3: 2025-12 | B3: =SUMIFS(Transactions!$G$2:$G$201,Transactions!$I$2:$I$201,$A3,Transactions!$D$2:$D$201,"Income - Recurring Direct Credit") -> 0 | C3: =SUMIFS(Transactions!$G$2:$G$201,Transactions!$I$2:$I$201,$A3,Transactions!$D$2:$D$201,"Income - Refund/Reimbursement")+SUMIFS(Transactions!$G$2:$G$201,Transactions!$I$2:$I$201,$A3,Transactions!$D$2:$D$201,"Income - Other Credit") -> 0 | D3: =SUMIFS(Transactions!$G$2:$G$201,Transactions!$I$2:$I$201,$A3,Transactions!$D$2:$D$201,"Transfer In") -> 0 | E3: =SUMIFS(Transactions!$F$2:$F$201,Transactions!$I$2:$I$201,$A3)-SUMIFS(Transactions!$F$2:$F$201,Transactions!$I$2:$I$201,$A3,Transactions!$D$2:$D$201,"Transfer Out") -> 0 | F3: =SUMIFS(Transactions!$F$2:$F$201,Transactions!$I$2:$I$201,$A3,Transactions!$D$2:$D$201,"Transfer Out") -> 0 | G3: =B3+C3+D3-E3-F3 -> 0

Sheet Budget
A1: Suggested Monthly Budget
A2: Recurring-income baseline | B2: =MEDIAN('Monthly Summary'!B2) -> 0
A4: Category | B4: 2025-11 | C4: Average | D4: Suggested Cap | E4: Cap vs Avg | F4: Comment
A5: Housing - Rent | B5: =SUMIFS(Transactions!$F$2:$F$201,Transactions!$I$2:$I$201,"2025-11",Transactions!$D$2:$D$201,$A5) -> 0 | C5: =AVERAGE(B5:B5) -> 0 | D5: 3683 | E5: =D5-C5 -> 0 | F5: Fortnightly $1,700 normalized to 26 payments / 12 months.
A6: Groceries | B6: =SUMIFS(Transactions!$F$2:$F$201,Transactions!$I$2:$I$201,"2025-11",Transactions!$D$2:$D$201,$A6) -> 0 | C6: =AVERAGE(B6:B6) -> 0 | D6: 550 | E6: =D6-C6 -> 0 | F6: Baseline allowance for supermarket / grocery spending.
A7: Dining & Coffee | B7: =SUMIFS(Transactions!$F$2:$F$201,Transactions!$I$2:$I$201,"2025-11",Transactions!$D$2:$D$201,$A7) -> 0 | C7: =AVERAGE(B7:B7) -> 0 | D7: 650 | E7: =D7-C7 -> 0 | F7: A controllable category; target is below the observed run-rate.
A8: Utilities & Phone | B8: =SUMIFS(Transactions!$F$2:$F$201,Transactions!$I$2:$I$201,"2025-11",Transactions!$D$2:$D$201,$A8) -> 0 | C8: =AVERAGE(B8:B8) -> 0 | D8: 350 | E8: =D8-C8 -> 0 | F8: Smooths irregular billing months.
A9: Transport | B9: =SUMIFS(Transactions!$F$2:$F$201,Transactions!$I$2:$I$201,"2025-11",Transactions!$D$2:$D$201,$A9) -> 0 | C9: =AVERAGE(B9:B9) -> 0 | D9: 450 | E9: =D9-C9 -> 0 | F9: Allows for Opal/Uber/fuel/taxis.
A10: Fitness & Memberships | B10: =SUMIFS(Transactions!$F$2:$F$201,Transactions!$I$2:$I$201,"2025-11",Transactions!$D$2:$D$201,$A10) -> 0 | C10: =AVERAGE(B10:B10) -> 0 | D10: 354 | E10: =D10-C10 -> 0 | F10: Approximately current recurring run-rate.
A11: Health & Pharmacy | B11: =SUMIFS(Transactions!$F$2:$F$201,Transactions!$I$2:$I$201,"2025-11",Transactions!$D$2:$D$201,$A11) -> 0 | C11: =AVERAGE(B11:B11) -> 0 | D11: 400 | E11: =D11-C11 -> 0 | F11: Buffer for pharmacy/medical variability.
A12: Shopping | B12: =SUMIFS(Transactions!$F$2:$F$201,Transactions!$I$2:$I$201,"2025-11",Transactions!$D$2:$D$201,$A12) -> 0 | C12: =AVERAGE(B12:B12) -> 0 | D12: 600 | E12: =D12-C12 -> 0 | F12: Main discretionary reduction target.
A13: Beauty & Personal Care | B13: =SUMIFS(Transactions!$F$2:$F$201,Transactions!$I$2:$I$201,"2025-11",Transactions!$D$2:$D$201,$A13) -> 0 | C13: =AVERAGE(B13:B13) -> 0 | D13: 150 | E13: =D13-C13 -> 0 | F13: Use as a monthly cap / sinking fund.
A14: Home & Household | B14: =SUMIFS(Transactions!$F$2:$F$201,Transactions!$I$2:$I$201,"2025-11",Transactions!$D$2:$D$201,$A14) -> 0 | C14: =AVERAGE(B14:B14) -> 0 | D14: 250 | E14: =D14-C14 -> 0 | F14: Sinking fund for irregular household purchases.
A15: Entertainment & Experiences | B15: =SUMIFS(Transactions!$F$2:$F$201,Transactions!$I$2:$I$201,"2025-11",Transactions!$D$2:$D$201,$A15) -> 0 | C15: =AVERAGE(B15:B15) -> 0 | D15: 100 | E15: =D15-C15 -> 0 | F15: Monthly leisure allowance.
A16: Subscriptions & Donations | B16: =SUMIFS(Transactions!$F$2:$F$201,Transactions!$I$2:$I$201,"2025-11",Transactions!$D$2:$D$201,$A16) -> 0 | C16: =AVERAGE(B16:B16) -> 0 | D16: 15 | E16: =D16-C16 -> 0 | F16: Recurring subscriptions/donations.
... A21: Other | B21: =SUMIFS(Transactions!$F$2:$F$201,Transactions!$I$2:$I$201,"2025-11",Transactions!$D$2:$D$201,$A21) -> 0 | C21: =AVERAGE(B21:B21) -> 0 | D21: 250 | E21: =D21-C21 -> 0 | F21: Buffer for merchants not yet confidently categorized.
A22: TOTAL MONTHLY SPEND | B22: =SUM(B5:B21) -> 0 | C22: =SUM(C5:C21) -> 0 | D22: =SUM(D5:D21) -> 0 | E22: =SUM(E5:E21) -> 0
A25: Budget outcome
A26: Income baseline | B26: =$B$2 -> 0
A27: Suggested monthly spend | B27: =D22 -> 0
A28: Implied monthly savings | B28: =B26-B27 -> 0
A29: Savings rate | B29: =IFERROR(B28/B26,0) -> 0

Sheet Review
A1: Date | B1: Description | C1: Category | D1: Amount | E1: Parse Status | F1: Page | G1: Why shown
A2: 45962 | B2: HAWAIIAN1734212522763 PARIS FR | C2: Other | D2: -35.16 | E2: High confidence | F2: 1 | G2: Uncategorized merchant
A3: 45962 | B3: THE TASTE OF ASIAN PTY MASCOT AUS | C3: Other | D3: -20 | E3: High confidence | F3: 1 | G3: Uncategorized merchant
A4: 45962 | B4: International Transaction Fee | C4: Bank Fees | D4: -18.64 | E4: Amount mismatch: columns -0.63, balance delta -18.64; used balance | F4: 1 | G4: Parser reconstruction / mismatch
A5: 45962 | B5: Liv Eat Mascot NS AUS | C5: Other | D5: -6.09 | E5: High confidence | F5: 1 | G5: Uncategorized merchant
A6: 45965 | B6: KEN'S MARKET 75-116 SEATTLE WA | C6: Other | D6: -4.21 | E6: High confidence | F6: 2 | G6: Uncategorized merchant
A7: 45965 | B7: AIRBNB * HMMCN3N8CD LONDON GB | C7: Other | D7: -144.88 | E7: High confidence | F7: 2 | G7: Uncategorized merchant
A8: 45965 | B8: International Transaction Fee | C8: Bank Fees | D8: -32.01 | E8: Amount mismatch: columns -0.84, balance delta -32.01; used balance | F8: 2 | G8: Parser reconstruction / mismatch
A9: 45965 | B9: International Transaction Fee | C9: Bank Fees | D9: -11.36 | E9: Amount mismatch: columns -0.38, balance delta -11.36; used balance | F9: 2 | G9: Parser reconstruction / mismatch
A10: 45965 | B10: SQ *PAGES & PAGES HONO Honolulu | C10: Other | D10: -7.64 | E10: High confidence | F10: 2 | G10: Uncategorized merchant
A11: 45966 | B11: SQ *SIFF CINEMA DOWNTO Seattle WA | C11: Other | D11: -15.31 | E11: High confidence | F11: 2 | G11: Uncategorized merchant
A12: 45966 | B12: SP MUTO.ARTONTHETABLE SEATTLE | C12: Other | D12: -159.35 | E12: High confidence | F12: 3 | G12: Uncategorized merchant
A13: 45966 | B13: XING FU TANG SEATTLE WA USA | C13: Other | D13: -14.16 | E13: High confidence | F13: 3 | G13: Uncategorized merchant
... A67: 45994 | B67: KUDOBOARD DENVER CO USA | C67: Other | D67: -15.72 | E67: High confidence | F67: 10 | G67: Uncategorized merchant

Sheet Assumptions
A1: Parsing & budgeting assumptions
A3: Source | B3: Statement.pdf | C3: Parser | D3: PyMuPDF text + coordinate columns; no OCR / no network
A4: Statement period | B4: 2025-11-01 to 2025-12-04 | C4: Complete budget months | D4: 2025-11
A5: Opening balance | B5: 7659.32 | C5: Closing balance | D5: 5034.38
A6: Transactions | B6: 200 | C6: Reconstructed / mismatched rows | D6: 14
A7: Reconciliation | B7: Every amount is checked against the running balance. | C7: Failure mode | D7: Workbook is not written if the statement does not reconcile.
A8: Income baseline | B8: Direct Credit / salary / wages are recurring income unless identified as refunds. | C8: Transfers | D8: Transfers and cash deposits are kept separate from recurring income.
A9: Categories | B9: Merchant categories are heuristic and editable in Transactions column D. | C9: Permanent rules | D9: Edit CATEGORY_RULES near the top of this script.
A10: Budget | B10: Suggested caps are editable near the top of this script. | C10: Partial months | D10: Only complete calendar months are used when the statement period allows it.

Sheet Dashboard
A1: Personal Budget Dashboard
A3: Period | B3: 2025-11-01 to 2025-12-04 | D3: Recurring income baseline | E3: =Budget!B2 -> 0
A4: Transactions | B4: 200 | D4: Suggested monthly budget | E4: =Budget!D22 -> 0
A5: Opening balance | B5: 7659.32 | D5: Implied monthly savings | E5: =E3-E4 -> 0
A6: Closing balance | B6: 5034.38 | D6: Implied savings rate | E6: =IFERROR(E5/E3,0) -> 0
A7: Rows needing parser reconstruction | B7: 14
